<?xml version="1.0"?>
<robot
  name="AUBO_HRM_R">
  <dh_type type="modified"/>
  <safety_para singularity_consistent="0.02 0.01 10 0.2 0.045 10"/>
  <friction_coeff value="0.5"/>
  <link
    name="link0">
    <inertial>
      <origin
        xyz="0.000007 0.000002 0.015501"
        rpy="0 0 0" />
      <mass
        value="1.036000" />
      <inertia
        ixx="0.000836" ixy="-0.000000" ixz="-0.000000" iyy="0.000835" iyz="-0.000000" izz="0.000658" />
    </inertial>
    <visual>
      <origin
        xyz="0 0 0"
        rpy="0 0 0" />
      <geometry>
        <mesh filename="package://aubo_description/meshes/AUBO_HRM_R/visual/link0.3ds" />
      </geometry>
      <material
        name="">
        <color
          rgba="0.752941176470588 0.752941176470588 0.752941176470588 1" />
      </material>
    </visual>
    <collision>
      <origin
        xyz="0 0 0"
        rpy="0 0 0" />
      <geometry>
        <mesh filename="package://aubo_description/meshes/AUBO_HRM_R/collision/link0.STL" />
      </geometry>
    </collision>
  </link>
  <link
    name="link1">
    <inertial>
      <origin
        xyz="0.000000 -0.000725 -0.029524"
        rpy="0 0 0" />
      <mass
        value="0.222000" />
      <inertia
        ixx="0.000545" ixy="-0.000000" ixz="-0.000000" iyy="0.000279" iyz="0.000045" izz="0.000505" />
    </inertial>
    <visual>
      <origin
        xyz="0 0 0"
        rpy="0 0 0" />
      <geometry>
        <mesh filename="package://aubo_description/meshes/AUBO_HRM_R/visual/link1.3ds" />
      </geometry>
      <material
        name="">
        <color
          rgba="0.752941176470588 0.752941176470588 0.752941176470588 1" />
      </material>
    </visual>
    <collision>
      <origin
        xyz="0 0 0"
        rpy="0 0 0" />
      <geometry>
        <mesh filename="package://aubo_description/meshes/AUBO_HRM_R/collision/link1.STL" />
      </geometry>
    </collision>
  </link>
  <joint
    name="joint1"
    type="revolute">
    <origin
      xyz="0 0 0.0767"
      rpy="0 0 0" />
    <parent
      link="link0" />
    <child
      link="link1" />
    <axis
      xyz="0 0 1" />
    <limit lower="-3.14159265358979" upper="0.785398163397448" effort="40" start_stop="82" velocity="3.14159265358979" />
    <property inertia="1.24" damping="0" stiffness="0" offset="0" motor_constant="5.31" ratio="100" protect_max_torque="0" equa_inertia="0" />
  </joint>
  <link
    name="link2">
    <inertial>
      <origin
        xyz="0.000000 0.000473 0.006864"
        rpy="0 0 0" />
      <mass
        value="1.226000" />
      <inertia
        ixx="0.001198" ixy="-0.000000" ixz="-0.000000" iyy="0.001180" iyz="0.000003" izz="0.000952" />
    </inertial>
    <visual>
      <origin
        xyz="0 0 0"
        rpy="0 0 0" />
      <geometry>
        <mesh filename="package://aubo_description/meshes/AUBO_HRM_R/visual/link2.3ds" />
      </geometry>
      <material
        name="">
        <color
          rgba="0.75294 0.75294 0.75294 1" />
      </material>
    </visual>
    <collision>
      <origin
        xyz="0 0 0"
        rpy="0 0 0" />
      <geometry>
        <mesh filename="package://aubo_description/meshes/AUBO_HRM_R/collision/link2.STL" />
      </geometry>
    </collision>
  </link>
  <joint
    name="joint2"
    type="revolute">
    <origin
      xyz="0 0 0.0"
      rpy="-1.5707963267948966192313216916398 -1.5707963267948966192313216916398 0" />
    <parent
      link="link1" />
    <child
      link="link2" />
    <axis
      xyz="0 0 1" />
    <limit lower="-1.74532925199433" upper="0" effort="40" start_stop="82" velocity="3.14159265358979" />
    <property inertia="1.24" damping="0" stiffness="0" offset="0" motor_constant="5.31" ratio="100" protect_max_torque="0" equa_inertia="0" />
  </joint>
  <link
    name="link3">
    <inertial>
      <origin
        xyz="0.000247 -0.003673 -0.081504"
        rpy="0 0 0" />
      <mass
        value="1.824000" />
      <inertia
        ixx="0.014207" ixy="-0.000002" ixz="-0.000016" iyy="0.013974" iyz="0.000547" izz="0.001323" />
    </inertial>
    <visual>
      <origin
        xyz="0 0 0"
        rpy="0 0 0" />
      <geometry>
        <mesh filename="package://aubo_description/meshes/AUBO_HRM_R/visual/link3.3ds" />
      </geometry>
      <material
        name="">
        <color
          rgba="0.752941176470588 0.752941176470588 0.752941176470588 1" />
      </material>
    </visual>
    <collision>
      <origin
        xyz="0 0 0"
        rpy="0 0 0" />
      <geometry>
        <mesh filename="package://aubo_description/meshes/AUBO_HRM_R/collision/link3.STL" />
      </geometry>
    </collision>
  </link>
  <joint
    name="joint3"
    type="revolute">
    <origin
      xyz="0 0.253 0"
      rpy="-1.5707963267948966192313216916398 0 0" />
    <parent
      link="link2" />
    <child
      link="link3" />
    <axis
      xyz="0 0 1" />
    <limit lower="-2.26892802759263" upper="2.26892802759263" effort="22" start_stop="42" velocity="4.18879020478639" />
    <property inertia="0.2" damping="0" stiffness="0" offset="0" motor_constant="4.5" ratio="100" protect_max_torque="0" equa_inertia="0" />
  </joint>
  <link
    name="link4">
    <inertial>
      <origin
        xyz="0.002765 0.020714 0.006089"
        rpy="0 0 0" />
      <mass
        value="0.123000" />
      <inertia
        ixx="0.000241" ixy="-0.000004" ixz="0.000002" iyy="0.000211" iyz="0.000006" izz="0.000125" />
    </inertial>
    <visual>
      <origin
        xyz="0 0 0"
        rpy="0 0 0" />
      <geometry>
        <mesh filename="package://aubo_description/meshes/AUBO_HRM_R/visual/link4.3ds" />
      </geometry>
      <material
        name="">
        <color
          rgba="0.75294 0.75294 0.75294 1" />
      </material>
    </visual>
    <collision>
      <origin
        xyz="0 0 0"
        rpy="0 0 0" />
      <geometry>
        <mesh filename="package://aubo_description/meshes/AUBO_HRM_R/collision/link4.STL" />
      </geometry>
    </collision>
  </link>
  <joint
    name="joint4"
    type="revolute">
    <origin
      xyz="0 0 0"
      rpy="1.5707963267948966192313216916398 0 0" />
    <parent
      link="link3" />
    <child
      link="link4" />
    <axis
      xyz="0 0 1" />
    <limit lower="-2.26892802759263" upper="0" effort="22" start_stop="42" velocity="4.18879020478639" />
    <property inertia="0.2" damping="0" stiffness="0" offset="0" motor_constant="4.5" ratio="100" protect_max_torque="0" equa_inertia="0" />
  </joint>
  <link
    name="link5">
    <inertial>
      <origin
        xyz="-0.000563 -0.005092 -0.108798"
        rpy="0 0 0" />
      <mass
        value="1.010000" />
      <inertia
        ixx="0.002286" ixy="-0.000027" ixz="0.000035" iyy="0.002080" iyz="0.000228" izz="0.000629" />
    </inertial>
    <visual>
      <origin
        xyz="0 0 0"
        rpy="0 0 0" />
      <geometry>
        <mesh filename="package://aubo_description/meshes/AUBO_HRM_R/visual/link5.3ds" />
      </geometry>
      <material
        name="">
        <color
          rgba="0.752941176470588 0.752941176470588 0.752941176470588 1" />
      </material>
    </visual>
    <collision>
      <origin
        xyz="0 0 0"
        rpy="0 0 0" />
      <geometry>
        <mesh filename="package://aubo_description/meshes/AUBO_HRM_R/collision/link5.STL" />
      </geometry>
    </collision>
  </link>
  <joint
    name="joint5"
    type="revolute">
    <origin
      xyz="0 0.2355 0"
      rpy="-1.5707963267948966192313216916398 0 0" />
    <parent
      link="link4" />
    <child
      link="link5" />
    <axis
      xyz="0 0 1" />
    <limit lower="-2.26892802759263" upper="2.26892802759263" effort="8" start_stop="15" velocity="3.14159265358979" />
    <property inertia="0.085" damping="0" stiffness="0" offset="0" motor_constant="4.63" ratio="100" protect_max_torque="0" equa_inertia="0" />
  </joint>
  <link
    name="link6">
    <inertial>
      <origin
        xyz="0.000000 -0.005048 0.000947"
        rpy="0 0 0" />
      <mass
        value="0.487000" />
      <inertia
        ixx="0.000270" ixy="-0.000000" ixz="-0.000000" iyy="0.000208" iyz="-0.000012" izz="0.000250" />
    </inertial>
    <visual>
      <origin
        xyz="0 0 0"
        rpy="0 0 0" />
      <geometry>
        <mesh filename="package://aubo_description/meshes/AUBO_HRM_R/visual/link6.3ds" />
      </geometry>
      <material
        name="">
        <color
          rgba="0.75294 0.75294 0.75294 1" />
      </material>
    </visual>
    <collision>
      <origin
        xyz="0 0 0"
        rpy="0 0 0" />
      <geometry>
        <mesh filename="package://aubo_description/meshes/AUBO_HRM_R/collision/link6.STL" />
      </geometry>
    </collision>
  </link>
  <joint
    name="joint6"
    type="revolute">
    <origin
      xyz="0 0 0"
      rpy="1.5707963267948966192313216916398 -1.5707963267948966192313216916398 0" />
    <parent
      link="link5" />
    <child
      link="link6" />
    <axis
      xyz="0 0 1" />
    <limit lower="-1.30899693899575" upper="1.30899693899575" effort="8" start_stop="15" velocity="3.14159265358979" />
    <property inertia="0.085" damping="0" stiffness="0" offset="0" motor_constant="4.63" ratio="100" protect_max_torque="0" equa_inertia="0" />
  </joint>
  <link
    name="link7">
    <inertial>
      <origin
        xyz="-0.000016 -0.066640 0.015498"
        rpy="0 0 0" />
      <mass
        value="0.228000" />
      <inertia
        ixx="0.000303" ixy="-0.000000" ixz="-0.000000" iyy="0.000168" iyz="-0.000088" izz="0.000265" />
    </inertial>
    <visual>
      <origin
        xyz="0 0 0"
        rpy="0 0 0" />
      <geometry>
        <mesh filename="package://aubo_description/meshes/AUBO_HRM_R/visual/link7.3ds" />
      </geometry>
      <material
        name="">
        <color
          rgba="0.75294 0.75294 0.75294 1" />
      </material>
    </visual>
    <collision>
      <origin
        xyz="0 0 0"
        rpy="0 0 0" />
      <geometry>
        <mesh filename="package://aubo_description/meshes/AUBO_HRM_R/collision/link7.STL" />
      </geometry>
    </collision>
  </link>
  <joint
    name="joint7"
    type="revolute">
    <origin
      xyz="0 0 0"
      rpy="1.5707963267948966192313216916398 -1.5707963267948966192313216916398 0" />
    <parent
      link="link6" />
    <child
      link="link7" />
    <axis
      xyz="0 0 1" />
    <limit lower="-1.30899693899575" upper="1.30899693899575" effort="8" start_stop="15" velocity="3.14159265358979" />
    <property inertia="0.085" damping="0" stiffness="0" offset="0" motor_constant="4.63" ratio="100" protect_max_torque="0" equa_inertia="0" />
  </joint>
  <link name="flange"/>
  <joint name="flange" type="fixed">
    <origin rpy="1.5707963267948966192313216916398 0 0" xyz="0 -0.1115 0"/>
    <parent link="link7"/>
    <child link="flange"/>
  </joint>

<link name="world" />

  <joint name="world_joint" type="fixed">
    <parent link="world" />
    <child link = "link0" />
    <origin xyz="0.0 0.0 0.0" rpy="0.0 0.0 0.0" />
  </joint>
</robot>
