<?xml version="1.0"?>
<robot name="aubo_i5_33">
  <dh_type type="modified"/>
  <safety_para singularity_consistent="0.02 0.01 10 0.2 0.045 10"/>
  <link name="base_link">
    <inertial>
      <origin rpy="0 0 0" xyz="-5.5723E-10 -0.00053181 0.016438"/>
      <mass value="0.5499"/>
      <inertia ixx="0.0011098" ixy="1.3184E-11" ixz="3.3523E-12" iyy="0.0011174" iyz="-1.2673E-05" izz="0.002061"/>
    </inertial>
    <visual>
      <origin rpy="0 0 0" xyz="0 0 0"/>
      <geometry>
        <mesh filename="package://aubo_description/meshes/aubo_i5_33/visual/link0.3ds"/>
      </geometry>
     <material name="black">
        <color rgba="0.25098 0.25098 0.25098 1"/>
      </material>
    </visual>
    <collision>
      <origin rpy="0 0 0" xyz="0 0 0"/>
      <geometry>
        <mesh filename="package://aubo_description/meshes/aubo_i5_33/collision/link0.STL"/>
      </geometry>
    </collision>
  </link>
  <link name="shoulder_Link">
    <inertial>
      <origin rpy="0 0 0" xyz="1.8797E-06 0.0063705 -0.014752"/>
      <mass value="1.4505"/>
      <inertia ixx="0.0032429" ixy="5.3132E-08" ixz="-1.3896E-08" iyy="0.0031222" iyz="-0.00024889" izz="0.0027718"/>
    </inertial>
    <visual>
      <origin rpy="0 0 0" xyz="0 0 0"/>
      <geometry>
        <mesh filename="package://aubo_description/meshes/aubo_i5_33/visual/link1.3ds"/>
      </geometry>
       <material name="orange">
        <color rgba="1 0.65098 0 1"/>
      </material>
    </visual>
    <collision>
      <origin rpy="0 0 0" xyz="0 0 0"/>
      <geometry>
        <mesh filename="package://aubo_description/meshes/aubo_i5_33/collision/link1.STL"/>
      </geometry>
    </collision>
  </link>
  <joint name="shoulder_joint" type="revolute">
    <origin rpy="0 0 3.1415926535897932384626433832795" xyz="0 0 0.122"/>
    <parent link="base_link"/>
    <child link="shoulder_Link"/>
    <axis xyz="0 0 1"/>
    <limit lower="-6.283185307179586476925286766559" upper="6.283185307179586476925286766559" effort="133" start_stop="207" velocity="2.5964" />
  </joint>
  <link name="upperArm_Link">
    <inertial>
      <origin rpy="0 0 0" xyz="0.304 1.1022E-06 0.0069544"/>
      <mass value="3.552"/>
      <inertia ixx="0.0075968" ixy="-3.9847E-07" ixz="1.2349E-09" iyy="0.28172" iyz="3.2578E-07" izz="0.28066"/>
    </inertial>
    <visual>
      <origin rpy="0 0 0" xyz="0 0 0"/>
      <geometry>
        <mesh filename="package://aubo_description/meshes/aubo_i5_33/visual/link2.3ds"/>
      </geometry>
       <material name="orange">
        <color rgba="1 0.65098 0 1"/>
      </material>
    </visual>
    <collision>
      <origin rpy="0 0 0" xyz="0 0 0"/>
      <geometry>
        <mesh filename="package://aubo_description/meshes/aubo_i5_33/collision/link2.STL"/>
      </geometry>
    </collision>
  </link>
  <joint name="upperArm_joint" type="revolute">
    <origin rpy="-1.5707963267948966192313216916398 -1.5707963267948966192313216916398 0" xyz="0 0.1215 0"/>
    <parent link="shoulder_Link"/>
    <child link="upperArm_Link"/>
    <axis xyz="0 0 1"/>
    <limit lower="-6.283185307179586476925286766559" upper="6.283185307179586476925286766559" effort="133" start_stop="207" velocity="2.5964" />
  </joint>
  <link name="foreArm_Link">
    <inertial>
      <origin rpy="0 0 0" xyz="0.47998 -3.2016E-06 0.096041"/>
      <mass value="0.90769"/>
      <inertia ixx="0.0010698" ixy="-3.7747E-07" ixz="0.00094801" iyy="0.034604" iyz="2.1581E-07" izz="0.034439"/>
    </inertial>
    <visual>
      <origin rpy="0 0 0" xyz="0 0 0"/>
      <geometry>
        <mesh filename="package://aubo_description/meshes/aubo_i5_33/visual/link3.3ds"/>
      </geometry>
        <material name="orange">
        <color rgba="1 0.65098 0 1"/>
      </material>
    </visual>
    <collision>
      <origin rpy="0 0 0" xyz="0 0 0"/>
      <geometry>
        <mesh filename="package://aubo_description/meshes/aubo_i5_33/collision/link3.STL"/>
      </geometry>
    </collision>
  </link>
  <joint name="foreArm_joint" type="revolute">
    <origin rpy="-3.1415926535897932384626433832795 0 0" xyz="0.608 0 0"/>
    <parent link="upperArm_Link"/>
    <child link="foreArm_Link"/>
    <axis xyz="0 0 1"/>
    <limit lower="-6.283185307179586476925286766559" upper="6.283185307179586476925286766559" effort="133" start_stop="207" velocity="2.5964" />
  </joint>
  <link name="wrist1_Link">
    <inertial>
      <origin rpy="0 0 0" xyz="4.9891E-07 0.013119 -0.0045696"/>
      <mass value="0.44686"/>
      <inertia ixx="0.00048851" ixy="-3.823E-09" ixz="8.3651E-09" iyy="0.00036127" iyz="-3.9646E-05" izz="0.00046417"/>
    </inertial>
    <visual>
      <origin rpy="0 0 0" xyz="0 0 0"/>
      <geometry>
        <mesh filename="package://aubo_description/meshes/aubo_i5_33/visual/link4.3ds"/>
      </geometry>
     <material name="orange">
        <color rgba="1 0.65098 0 1"/>
      </material>
    </visual>
    <collision>
      <origin rpy="0 0 0" xyz="0 0 0"/>
      <geometry>
        <mesh filename="package://aubo_description/meshes/aubo_i5_33/collision/link4.STL"/>
      </geometry>
    </collision>
  </link>
  <joint name="wrist1_joint" type="revolute">
    <origin rpy="3.1415926535897932384626433832795 -1.1102E-16 1.5707963267948966192313216916398" xyz="0.6395 0 0"/>
    <parent link="foreArm_Link"/>
    <child link="wrist1_Link"/>
    <axis xyz="0 0 1"/>
    <limit lower="-6.283185307179586476925286766559" upper="6.283185307179586476925286766559" effort="13.5" start_stop="34" velocity="3.1105" />
  </joint>
  <link name="wrist2_Link">
    <inertial>
      <origin rpy="0 0 0" xyz="-4.9891E-07 -0.013119 -0.0045696"/>
      <mass value="0.44686"/>
      <inertia ixx="0.00048851" ixy="-3.823E-09" ixz="-8.3651E-09" iyy="0.00036127" iyz="3.9646E-05" izz="0.00046417"/>
    </inertial>
    <visual>
      <origin rpy="0 0 0" xyz="0 0 0"/>
      <geometry>
        <mesh filename="package://aubo_description/meshes/aubo_i5_33/visual/link5.3ds"/>
      </geometry>
      <material name="orange">
        <color rgba="1 0.65098 0 1"/>
      </material>
    </visual>
    <collision>
      <origin rpy="0 0 0" xyz="0 0 0"/>
      <geometry>
        <mesh filename="package://aubo_description/meshes/aubo_i5_33/collision/link5.STL"/>
      </geometry>
    </collision>
  </link>
  <joint name="wrist2_joint" type="revolute">
    <origin rpy="-1.5707963267948966192313216916398 0 -1.6653E-16" xyz="0 0.1025 0"/>
    <parent link="wrist1_Link"/>
    <child link="wrist2_Link"/>
    <axis xyz="0 0 1"/>
    <limit lower="-6.283185307179586476925286766559" upper="6.283185307179586476925286766559" effort="13.5" start_stop="34" velocity="3.1105" />
  </joint>
  <link name="wrist3_Link">
    <inertial>
      <origin rpy="0 0 0" xyz="2.2512E-08 0.00029937 -0.018058"/>
      <mass value="0.14035"/>
      <inertia ixx="6.1524E-05" ixy="-1.0358E-10" ixz="3.0206E-11" iyy="5.9833E-05" iyz="4.033E-07" izz="9.5362E-05"/>
    </inertial>
    <visual>
      <origin rpy="0 0 0" xyz="0 0 0"/>
      <geometry>
        <mesh filename="package://aubo_description/meshes/aubo_i5_33/visual/link6.3ds"/>
      </geometry>
      <material name="black">
        <color rgba="0.25098 0.25098 0.25098"/>
      </material>
    </visual>
    <collision>
      <origin rpy="0 0 0" xyz="0 0 0"/>
      <geometry>
        <mesh filename="package://aubo_description/meshes/aubo_i5_33/collision/link6.STL"/>
      </geometry>
    </collision>
  </link>
  <joint name="wrist3_joint" type="revolute">
    <origin rpy="1.5707963267948966192313216916398 -1.6653E-16 0" xyz="0 -0.094 0"/>
    <parent link="wrist2_Link"/>
    <child link="wrist3_Link"/>
    <axis xyz="0 0 1"/>
    <limit lower="-6.283185307179586476925286766559" upper="6.283185307179586476925286766559" effort="13.5" start_stop="34" velocity="3.1105" />
  </joint>

  <link name="world" />

  <joint name="world_joint" type="fixed">
    <parent link="world" />
    <child link = "base_link" />
    <origin xyz="0.0 0.0 0.0" rpy="0.0 0.0 0.0" />
  </joint>
</robot>
