<?xml version="1.0"?>
<robot  name="aubo_i20L_1900">
  <dh_type type="modified"/>
  <safety_para singularity_consistent="0.02 0.01 10 0.2 0.045 10"/>
  <link name="base_link">
    <inertial>
      <origin xyz="-0.0002 0.0144 0.0349" rpy="0 0 0" />
      <mass value="3.4898" />
      <inertia ixx="0.0168" ixy="0.0000" ixz="0.0000" iyy="0.0135" iyz="0.0003" izz="0.0255" />
    </inertial>
    <visual>
      <origin xyz="0 0 0" rpy="0 0 0" />
      <geometry>
        <mesh filename="package://aubo_description/meshes/aubo_i20L_1900/visual/link0.DAE" />
      </geometry>
      <material name="">
        <color rgba="1 1 1 1" />
      </material>
    </visual>
    <collision>
      <origin xyz="0 0 0" rpy="0 0 0" />
      <geometry>
        <mesh filename="package://aubo_description/meshes/aubo_i20L_1900/collision/link0.STL" />
      </geometry>
    </collision>
  </link>

  <link name="shoulder_Link">
    <inertial>
      <origin xyz="-0.00002839 0.00362627 -0.02877145" rpy="0 0 0" />
      <mass value="15.98762671" />
      <inertia ixx="0.08130765" ixy="-0.00000624" ixz="0.00005596" iyy="0.08097661" iyz="-0.00225751" izz="0.06761993" />
    </inertial>
    <visual>
      <origin xyz="0 0 0" rpy="0 0 0" />
      <geometry>
        <mesh filename="package://aubo_description/meshes/aubo_i20L_1900/visual/link1.DAE" />
      </geometry>
      <material name="">
        <color rgba="1 1 1 1" />
      </material>
    </visual>
    <collision>
      <origin xyz="0 0 0" rpy="0 0 0" />
      <geometry>
        <mesh filename="package://aubo_description/meshes/aubo_i20L_1900/collision/link1.STL" />
      </geometry>
    </collision>
  </link>

  <joint name="shoulder_joint" type="revolute">
    <origin xyz="0 0 0.1855" rpy="0 0 3.1415926535897932384626433832795" />
    <parent link="base_link" />
    <child link="shoulder_Link" />
    <axis xyz="0 0 1" />
    <limit lower="-6.283185307179586476925286766559" upper="6.283185307179586476925286766559" effort="557" start_stop="800" velocity="2.5962" />
    <property inertia="9.5" damping="0" stiffness="0" offset="0" motor_constant="18.7" ratio="161"/>
  </joint>

  <link name="upperArm_Link">
    <inertial>
      <origin xyz="0.39050427 0.00001695 0.03023743" rpy="0 0 0" />
      <mass value="35.43624922" />
      <inertia ixx="0.17832661" ixy="0.0002088" ixz="-0.06050506" iyy="6.50664126" iyz="-0.00006999" izz="6.46959412" />
    </inertial>
    <visual>
      <origin xyz="0 0 0" rpy="0 0 0" />
      <geometry>
        <mesh filename="package://aubo_description/meshes/aubo_i20L_1900/visual/link2.DAE" />
      </geometry>
      <material name="">
        <color rgba="1 1 1 1" />
      </material>
    </visual>
    <collision>
      <origin xyz="0 0 0" rpy="0 0 0" />
      <geometry>
        <mesh filename="package://aubo_description/meshes/aubo_i20L_1900/collision/link2.STL" />
      </geometry>
    </collision>
  </link>

  <joint name="upperArm_joint" type="revolute">
    <origin xyz="0 0.1675 0" rpy="-1.5707963267948966192313216916398 -1.5707963267948966192313216916398 0" />
    <parent link="shoulder_Link" />
    <child link="upperArm_Link" />
    <axis xyz="0 0 1" />
    <limit lower="-3.054326190990076759616458844855" upper="3.054326190990076759616458844855" effort="557" start_stop="800" velocity="2.5962" />
    <property inertia="9.5" damping="0" stiffness="0" offset="0" motor_constant="18.70" ratio="161"/>
  </joint>

  <link name="foreArm_Link">
    <inertial>
      <origin xyz="0.51257096 -0.00001864 0.1077902" rpy="0 0 0" />
      <mass  value="6.38158507" />
      <inertia ixx="0.01264426" ixy="0.00004339" ixz="-0.00165711" iyy="0.66780388" iyz="0.00000571" izz="0.66650941" />
    </inertial>
    <visual>
      <origin xyz="0 0 0" rpy="0 0 0" />
      <geometry>
        <mesh filename="package://aubo_description/meshes/aubo_i20L_1900/visual/link3.DAE" />
      </geometry>
      <material name="">
        <color rgba="1 1 1 1" />
      </material>
    </visual>
    <collision>
      <origin xyz="0 0 0" rpy="0 0 0" />
      <geometry>
        <mesh filename="package://aubo_description/meshes/aubo_i20L_1900/collision/link3.STL" />
      </geometry>
    </collision>
  </link>

  <joint name="foreArm_joint" type="revolute">
    <origin xyz="0.953 0 0" rpy="-3.1415926535897932384626433832795 0 0" />
    <parent link="upperArm_Link" />
    <child link="foreArm_Link" />
    <axis xyz="0 0 1" />
    <limit lower="-3.054326190990076759616458844855" upper="3.054326190990076759616458844855" effort="267" start_stop="411" velocity="2.5962" />
    <property inertia="4.9" damping="0" stiffness="0" offset="0" motor_constant="10.1" ratio="101"/>
  </joint>

  <link name="wrist1_Link">
    <inertial>
      <origin xyz="0.00003637 0.01562881 -0.0015103" rpy="0 0 0" />
      <mass value="2.36997314" />
      <inertia ixx="0.00366744" ixy="0.00000645" ixz="-0.00000084" iyy="0.00218785" iyz="-0.00007755" izz="0.00361804" />
    </inertial>
    <visual>
      <origin xyz="0 0 0" rpy="0 0 0" />
      <geometry>
        <mesh filename="package://aubo_description/meshes/aubo_i20L_1900/visual/link4.DAE" />
      </geometry>
      <material name="">
        <color rgba="1 1 1 1" />
      </material>
    </visual>
    <collision>
      <origin xyz="0 0 0" rpy="0 0 0" />
      <geometry>
        <mesh filename="package://aubo_description/meshes/aubo_i20L_1900/collision/link4.STL" />
      </geometry>
    </collision>
  </link>

  <joint name="wrist1_joint" type="revolute">
    <origin xyz="0.8295 0 0" rpy="3.1415926535897932384626433832795 0 1.5707963267948966192313216916398" />
    <parent link="foreArm_Link" />
    <child link="wrist1_Link" />
    <axis xyz="0 0 1" />
    <limit lower="-3.054326190990076759616458844855" upper="3.054326190990076759616458844855" effort="49" start_stop="66" velocity="3.1102" />
    <property inertia="0.39" damping="0" stiffness="0" offset="0" motor_constant="7.64" ratio="101"/>
  </joint>

  <link name="wrist2_Link">
    <inertial>
      <origin xyz="-0.00003637 -0.01562881 -0.0015103" rpy="0 0 0" />
      <mass value="2.36997314" />
      <inertia ixx="0.00366744" ixy="0.00000645" ixz="0.00000084" iyy="0.00218785" iyz="0.00007755" izz="0.00361804" />
    </inertial>
    <visual>
      <origin xyz="0 0 0" rpy="0 0 0" />
      <geometry>
        <mesh filename="package://aubo_description/meshes/aubo_i20L_1900/visual/link5.DAE" />
      </geometry>
      <material name="">
        <color rgba="1 1 1 1" />
      </material>
    </visual>
    <collision>
      <origin xyz="0 0 0" rpy="0 0 0" />
      <geometry>
        <mesh filename="package://aubo_description/meshes/aubo_i20L_1900/collision/link5.STL" />
      </geometry>
    </collision>
  </link>

  <joint name="wrist2_joint" type="revolute">
    <origin xyz="0 0.1175 0" rpy="-1.5707963267948966192313216916398 0 0" />
    <parent link="wrist1_Link" />
    <child link="wrist2_Link" />
    <axis xyz="0 0 1" />
    <limit lower="-3.054326190990076759616458844855" upper="3.054326190990076759616458844855" effort="49" start_stop="66" velocity="3.1102" />
    <property inertia="0.39" damping="0" stiffness="0" offset="0" motor_constant="7.64" ratio="101"/>
  </joint>

  <link name="wrist3_Link">
    <inertial>
      <origin xyz="-0.00000145 0.00009268 -0.01872119" rpy="0 0 0" />
      <mass value="0.40421189" />
      <inertia ixx="0.00021838" ixy="0" ixz="0" iyy="0.00021132" iyz="0" izz="0.00036613" />
    </inertial>
    <visual>
      <origin xyz="0 0 0" rpy="0 0 0" />
      <geometry>
        <mesh filename="package://aubo_description/meshes/aubo_i20L_1900/visual/link6.DAE" />
      </geometry>
      <material name="">
        <color rgba="1 1 1 1" />
      </material>
    </visual>
    <collision>
      <origin xyz="0 0 0" rpy="0 0 0" />
      <geometry>
        <mesh filename="package://aubo_description/meshes/aubo_i20L_1900/collision/link6.STL" />
      </geometry>
    </collision>
  </link>

  <joint name="wrist3_joint" type="revolute">
    <origin xyz="0 -0.1035 0" rpy="1.5707963267948966192313216916398 0 1.7907E-15" />
    <parent link="wrist2_Link" />
    <child link="wrist3_Link" />
    <axis xyz="0 0 1" />
    <limit lower="-6.283185307179586476925286766559" upper="6.283185307179586476925286766559" effort="49" start_stop="66" velocity="3.1102" />
    <property inertia="0.39" damping="0" stiffness="0" offset="0" motor_constant="7.64" ratio="101"/>
  </joint>

  <link name="world" />

  <joint name="world_joint" type="fixed">
    <parent link="world" />
    <child link = "base_link" />
    <origin xyz="0.0 0.0 0.0" rpy="0.0 0.0 0.0" />
  </joint>
</robot>
