<?xml version="1.0" encoding="utf-8"?>
<!-- This URDF was automatically created by SolidWorks to URDF Exporter! Originally created by Stephen Brawner (brawner@gmail.com) 
     Commit Version: 1.5.1-0-g916b5db  Build Version: 1.5.7152.31018
     For more information, please see http://wiki.ros.org/sw_urdf_exporter -->
<robot
  name="aubo_iS7_A0">
  <dh_type type="modified"/>
  <safety_para singularity_consistent="0.02 0.01 10 0.2 0.045 10"/>	
  <collision_detection_para cutoff_frequency = "50.0 50.0 30.0 20.0"/>
  <link
    name="base_link">
    <inertial>
      <origin
        xyz="0.000380 0.004710 0.019130"
        rpy="0 0 0" />
      <mass
        value="2.022030" />  	 	 	 	 	 	 
      <inertia
        ixx="0.00676"
        ixy="-0.00004"
        ixz="-0.00001"
        iyy="0.00628"
        iyz="-0.00007"
        izz="0.01215" />
    </inertial>
    <visual>
      <origin
        xyz="0 0 0"
        rpy="0 0 0" />
      <geometry>
        <mesh
          filename="package://aubo_description/meshes/aubo_iS7_A0/visual/link0.3ds" />
      </geometry>
      <material
        name="">
        <color
          rgba="0.25098 0.25098 0.25098 1" />
      </material>
    </visual>
    <collision>
      <origin
        xyz="0 0 0"
        rpy="0 0 0" />
      <geometry>
        <mesh
          filename="package://aubo_description/meshes/aubo_iS7_A0/collision/link0.STL" />
      </geometry>
    </collision>
  </link>
  <link
    name="shoulder_Link">
    <inertial>
      <origin
        xyz="0.000000 0.010280 -0.024390"
        rpy="0 0 0" />
      <mass
        value="10.256280" /> 	 	 	 	 	 	 	 
      <inertia
        ixx="0.04731"
        ixy="0.00000"
        ixz="0.00000"
        iyy="0.04186"
        iyz="-0.00253"
        izz="0.03500" />
    </inertial>
    <visual>
      <origin
        xyz="0 0 0"
        rpy="0 0 0" />
      <geometry>
        <mesh
          filename="package://aubo_description/meshes/aubo_iS7_A0/visual/link1.3ds" />
      </geometry>
      <material
        name="">
        <color
          rgba="0.79216 0.81961 0.93333 1" />
      </material>
    </visual>
    <collision>
      <origin
        xyz="0 0 0"
        rpy="0 0 0" />
      <geometry>
        <mesh
          filename="package://aubo_description/meshes/aubo_iS7_A0/collision/link1.STL" />
      </geometry>
    </collision>
  </link>
  <joint
    name="shoulder_joint"
    type="revolute">
    <origin
      xyz="0 0 0.3952"
      rpy="0 0 3.14159265358979" />
    <parent
      link="base_link" />
    <child
      link="shoulder_Link" />
    <axis
      xyz="0 0 1" />
    <limit
      lower="-6.283185307179586476925286766559"
      upper="6.283185307179586476925286766559"
      effort="267"
      start_stop="433"
      velocity="2.5964" />
    <property inertia="2.0" damping="0" stiffness="0" offset="0" motor_constant="7.05" ratio="101" protect_max_torque="80.0" equa_inertia="1.5" collision_detection_para = "50 50 30 20"/>
  </joint>
  <link
    name="upperArm_Link">
    <inertial>
      <origin
        xyz="0.204000 0.000000 -0.019000"
        rpy="0 0 0" />
      <mass
        value="9.791100" /> 	 	 	 	 	 	 	 
      <inertia
        ixx="0.02410"
        ixy="0.00000"
        ixz="-0.03446"
        iyy="0.38927"
        iyz="0.00000"
        izz="0.38153" />
    </inertial>
    <visual>
      <origin
        xyz="0 0 0"
        rpy="0 0 0" />
      <geometry>
        <mesh
          filename="package://aubo_description/meshes/aubo_iS7_A0/visual/link2.3ds" />
      </geometry>
      <material
        name="">
        <color
          rgba="0.89804 0.91765 0.92941 1" />
      </material>
    </visual>
    <collision>
      <origin
        xyz="0 0 0"
        rpy="0 0 0" />
      <geometry>
        <mesh
          filename="package://aubo_description/meshes/aubo_iS7_A0/collision/link2.STL" />
      </geometry>
    </collision>
  </link>
  <joint
    name="upperArm_joint"
    type="revolute">
    <origin
      xyz="0 0.2025 0"
      rpy="-1.570796326781404 -1.570796326781404 0" />
    <parent
      link="shoulder_Link" />
    <child
      link="upperArm_Link" />
    <axis
      xyz="0 0 1" />
    <limit
      lower="-6.283185307179586476925286766559"
      upper="6.283185307179586476925286766559"
      effort="133"
      start_stop="204"
      velocity="2.5964" />
    <property inertia="2.0" damping="0" stiffness="0" offset="0" motor_constant="7.05" ratio="101" protect_max_torque="80.0" equa_inertia="1.5" collision_detection_para = "50 50 30 20"/>
  </joint>
  <link
    name="foreArm_Link">
    <inertial>
      <origin
        xyz="0.276455 -0.000015 0.091628"
        rpy="0 0 0" />
      <mass
        value="2.503678" /> 
      <inertia
        ixx="0.00296"
        ixy="0.00000"
        ixz="0.00042"
        iyy="0.05259"
        iyz="0.00000"
        izz="0.05208" />
    </inertial>
    <visual>
      <origin
        xyz="0 0 0"
        rpy="0 0 0" />
      <geometry>
        <mesh
          filename="package://aubo_description/meshes/aubo_iS7_A0/visual/link3.3ds" />
      </geometry>
      <material
        name="">
        <color
          rgba="1 0.72157 0.32941 1" />
      </material>
    </visual>
    <collision>
      <origin
        xyz="0 0 0"
        rpy="0 0 0" />
      <geometry>
        <mesh
          filename="package://aubo_description/meshes/aubo_iS7_A0/collision/link3.STL" />
      </geometry>
    </collision>
  </link>
  <joint
    name="foreArm_joint"
    type="revolute">
    <origin
      xyz="0.408 0 0"
      rpy="0 0 0" />
    <parent
      link="upperArm_Link" />
    <child
      link="foreArm_Link" />
    <axis
      xyz="0 0 1" />
    <limit
      lower="-6.283185307179586476925286766559"
      upper="6.283185307179586476925286766559"
      effort="133"
      start_stop="207"
      velocity="2.5964" />
    <property inertia="2.0" damping="0" stiffness="0" offset="0" motor_constant="7.05" ratio="101" protect_max_torque="60.0" equa_inertia="1.2" collision_detection_para = "50 50 30 20"/>
  </joint>
  <link
    name="wrist1_Link">
    <inertial>
      <origin
        xyz="0.000015 0.013974 -0.001734"
        rpy="0 0 0" />
      <mass
        value="1.495052" /> 	 	 	 	 	 	 	
      <inertia
        ixx="0.00163"
        ixy="0.00000"
        ixz="0.00000"
        iyy="0.00101"
        iyz="-0.00004"
        izz="0.00160 " />
    </inertial>
    <visual>
      <origin
        xyz="0 0 0"
        rpy="0 0 0" />
      <geometry>
        <mesh
          filename="package://aubo_description/meshes/aubo_iS7_A0/visual/link4.3ds" />
      </geometry>
      <material
        name="">
        <color
          rgba="1 0.72157 0.32941 1" />
      </material>
    </visual>
    <collision>
      <origin
        xyz="0 0 0"
        rpy="0 0 0" />
      <geometry>
        <mesh
          filename="package://aubo_description/meshes/aubo_iS7_A0/collision/link4.STL" />
      </geometry>
    </collision>
  </link>
  <joint
    name="wrist1_joint"
    type="revolute">
    <origin
      xyz="0.376 0 0"
      rpy="3.14159265358979 0 1.570796326781404" />
    <parent
      link="foreArm_Link" />
    <child
      link="wrist1_Link" />
    <axis
      xyz="0 0 1" />
    <limit
      lower="-6.283185307179586476925286766559"
      upper="6.283185307179586476925286766559"
      effort="13.5"
      start_stop="34"
      velocity="3.1105" />
    <property inertia="0.15" damping="0" stiffness="0" offset="0" motor_constant="5.94" ratio="81" protect_max_torque="16.0" equa_inertia="0.05" collision_detection_para = "50 50 30 20"/>
  </joint>
  <link
    name="wrist2_Link">
    <inertial>
      <origin
        xyz="-0.000015 -0.013974 -0.001734"
        rpy="0 0 0" />
      <mass
        value="1.495052" /> 	 	 	 	 	 	 	
      <inertia
        ixx="0.00163"
        ixy="0.00000"
        ixz="0.00000"
        iyy="0.00102"
        iyz="0.00000"
        izz="0.00193 " />
    </inertial>
    <visual>
      <origin
        xyz="0 0 0"
        rpy="0 0 0" />
      <geometry>
        <mesh
          filename="package://aubo_description/meshes/aubo_iS7_A0/visual/link5.3ds" />
      </geometry>
      <material
        name="">
        <color
          rgba="1 0.72157 0.32941 1" />
      </material>
    </visual>
    <collision>
      <origin
        xyz="0 0 0"
        rpy="0 0 0" />
      <geometry>
        <mesh
          filename="package://aubo_description/meshes/aubo_iS7_A0/collision/link5.STL"/>
      </geometry>
    </collision>
  </link>
  <joint
    name="wrist2_joint"
    type="revolute">
    <origin
      xyz="0 0.1025 0"
      rpy="-1.570796326781404 0 0" />
    <parent
      link="wrist1_Link" />
    <child
      link="wrist2_Link" />
    <axis
      xyz="0 0 1" />
    <limit
      lower="-6.283185307179586476925286766559"
      upper="6.283185307179586476925286766559"
      effort="13.5"
      start_stop="34"
      velocity="3.1105" />
    <property inertia="0.15" damping="0" stiffness="0" offset="0" motor_constant="5.94" ratio="81" protect_max_torque="16.0" equa_inertia="0.05" collision_detection_para = "50 50 30 20"/>
  </joint>
  <link
    name="wrist3_Link">
    <inertial>
      <origin
        xyz="-0.000462 0.001234 -0.017120"
        rpy="0 0 0" />
      <mass
        value="0.247173" />  	 	 	 	 	 	
      <inertia
        ixx="0.00013"
        ixy="0.00000"
        ixz="0.00000"
        iyy="0.00013"
        iyz="0.00000"
        izz="0.00021" />
    </inertial>
    <visual>
      <origin
        xyz="0 0 0"
        rpy="0 0 0" />
      <geometry>
        <mesh
          filename="package://aubo_description/meshes/aubo_iS7_A0/visual/link6.3ds" />
      </geometry>
      <material
        name="">
        <color
          rgba="0.89804 0.91765 0.92941 1" />
      </material>
    </visual>
    <collision>
      <origin
        xyz="0 0 0"
        rpy="0 0 0" />
      <geometry>
        <mesh
          filename="package://aubo_description/meshes/aubo_iS7_A0/collision/link6.STL" />
      </geometry>
    </collision>
  </link>
  <joint
    name="wrist3_joint"
    type="revolute">
    <origin
      xyz="0 -0.094 0"
      rpy="1.570796326781404 0.0 0.0" />
    <parent
      link="wrist2_Link" />
    <child
      link="wrist3_Link" />
    <axis
      xyz="0 0 1" />
    <limit
      lower="-6.283185307179586476925286766559"
      upper="6.283185307179586476925286766559"
      effort="13.5"
      start_stop="34"
      velocity="3.1105" />
    <property inertia="0.15" damping="0" stiffness="0" offset="0" motor_constant="5.94" ratio="81" protect_max_torque="10.0" equa_inertia="0.01" collision_detection_para = "50 50 30 20"/>
  </joint>
  <link name="world" />

  <joint name="base_joint" type="fixed">
    <parent link="world" />
    <child link = "base_link" />
    <origin xyz="0.0 0.0 0.0" rpy="0.0 0.0 0.0" />
  </joint>
</robot>
