<?xml version="1.0"?>
<robot name="aubo_i5L">
  <dh_type type="modified"/>
  <safety_para singularity_consistent="0.02 0.01 10 0.2 0.045 10"/>
  <link name="base_link">
    <inertial>
      <origin rpy="0 0 0" xyz="0.000129 0.001249 0.016678"/>
      <mass value="1.53902"/>
      <inertia ixx="0.003278" ixy="-0.000001" ixz="-0.000001" iyy="0.003017" iyz="-0.000048" izz="0.005841"/>
    </inertial>
    <visual>
      <origin rpy="0 0 0" xyz="0 0 0"/>
      <geometry>
        <mesh filename="package://aubo_description/meshes/aubo_i5L/visual/link0.DAE"/>
      </geometry>
     <material name="black">
        <color rgba="0.25098 0.25098 0.25098 1"/>
      </material>
    </visual>
    <collision>
      <origin rpy="0 0 0" xyz="0 0 0"/>
      <geometry>
        <mesh filename="package://aubo_description/meshes/aubo_i5L/collision/link0.STL"/>
      </geometry>
    </collision>
  </link>
  <link name="shoulder_Link">
    <inertial>
      <origin rpy="0 0 0" xyz="-0.00001 0.001807 -0.013854"/>
      <mass value="4.848581"/>
      <inertia ixx="0.011842" ixy="0.0" ixz="0.000004" iyy="0.0118" iyz="-0.000103" izz="0.008103"/>
    </inertial>
    <visual>
      <origin rpy="0 0 0" xyz="0 0 0"/>
      <geometry>
        <mesh filename="package://aubo_description/meshes/aubo_i5L/visual/link1.DAE"/>
      </geometry>
       <material name="orange">
        <color rgba="1 0.65098 0 1"/>
      </material>
    </visual>
    <collision>
      <origin rpy="0 0 0" xyz="0 0 0"/>
      <geometry>
        <mesh filename="package://aubo_description/meshes/aubo_i5L/collision/link1.STL"/>
      </geometry>
    </collision>
  </link>
  <joint name="shoulder_joint" type="revolute">
    <origin rpy="0 0 3.1415926535897932384626433832795" xyz="0 0 0.122"/>
    <parent link="base_link"/>
    <child link="shoulder_Link"/>
    <axis xyz="0 0 1"/>
    <limit lower="-3.054326190990076759616458844855" upper="3.054326190990076759616458844855" effort="133" start_stop="207" velocity="2.5964" />
    <property inertia="2.0" damping="0" stiffness="0" offset="0" motor_constant="8.72" ratio="121"/>
  </joint>
  <link name="upperArm_Link">
    <inertial>
      <origin rpy="0 0 0" xyz="0.304 0 0.007104"/>
      <mass value="11.497272"/>
      <inertia ixx="0.027242" ixy="0.000032" ixz="0.0" iyy="0.960999" iyz="0.0" izz="0.953225"/>
    </inertial>
    <visual>
      <origin rpy="0 0 0" xyz="0 0 0"/>
      <geometry>
        <mesh filename="package://aubo_description/meshes/aubo_i5L/visual/link2.DAE"/>
      </geometry>
       <material name="orange">
        <color rgba="1 0.65098 0 1"/>
      </material>
    </visual>
    <collision>
      <origin rpy="0 0 0" xyz="0 0 0"/>
      <geometry>
        <mesh filename="package://aubo_description/meshes/aubo_i5L/collision/link2.STL"/>
      </geometry>
    </collision>
  </link>
  <joint name="upperArm_joint" type="revolute">
    <origin rpy="-1.5707963267948966192313216916398 -1.5707963267948966192313216916398 0" xyz="0 0.1215 0"/>
    <parent link="shoulder_Link"/>
    <child link="upperArm_Link"/>
    <axis xyz="0 0 1"/>
    <limit lower="-3.054326190990076759616458844855" upper="3.054326190990076759616458844855" effort="133" start_stop="207" velocity="2.5964" />
    <property inertia="2.0" damping="0" stiffness="0" offset="0" motor_constant="8.72" ratio="121"/>
  </joint>
  <link name="foreArm_Link">
    <inertial>
      <origin rpy="0 0 0" xyz="0.432656 -0.000023 0.095804"/>
      <mass value="3.456221"/>
      <inertia ixx="0.004364" ixy="0.000018" ixz="0.001188" iyy="0.210628" iyz="0.000004" izz="0.209901"/>
    </inertial>
    <visual>
      <origin rpy="0 0 0" xyz="0 0 0"/>
      <geometry>
        <mesh filename="package://aubo_description/meshes/aubo_i5L/visual/link3.DAE"/>
      </geometry>
        <material name="orange">
        <color rgba="1 0.65098 0 1"/>
      </material>
    </visual>
    <collision>
      <origin rpy="0 0 0" xyz="0 0 0"/>
      <geometry>
        <mesh filename="package://aubo_description/meshes/aubo_i5L/collision/link3.STL"/>
      </geometry>
    </collision>
  </link>
  <joint name="foreArm_joint" type="revolute">
    <origin rpy="-3.1415926535897932384626433832795 0 0" xyz="0.608 0 0"/>
    <parent link="upperArm_Link"/>
    <child link="foreArm_Link"/>
    <axis xyz="0 0 1"/>
    <limit lower="-3.054326190990076759616458844855" upper="3.054326190990076759616458844855" effort="133" start_stop="207" velocity="2.5964" />
    <property inertia="2.0" damping="0" stiffness="0" offset="0" motor_constant="8.72" ratio="121"/>
  </joint>
  <link name="wrist1_Link">
    <inertial>
      <origin rpy="0 0 0" xyz="0.000038 0.011278 -0.001539"/>
      <mass value="1.628022"/>
      <inertia ixx="0.001951" ixy="0.000003" ixz="0.000001" iyy="0.001154" iyz="-0.000042" izz="0.001931"/>
    </inertial>
    <visual>
      <origin rpy="0 0 0" xyz="0 0 0"/>
      <geometry>
        <mesh filename="package://aubo_description/meshes/aubo_i5L/visual/link4.DAE"/>
      </geometry>
     <material name="orange">
        <color rgba="1 0.65098 0 1"/>
      </material>
    </visual>
    <collision>
      <origin rpy="0 0 0" xyz="0 0 0"/>
      <geometry>
        <mesh filename="package://aubo_description/meshes/aubo_i5L/collision/link4.STL"/>
      </geometry>
    </collision>
  </link>
  <joint name="wrist1_joint" type="revolute">
    <origin rpy="3.1415926535897932384626433832795 0 1.5707963267948966192313216916398" xyz="0.6395 0 0"/>
    <parent link="foreArm_Link"/>
    <child link="wrist1_Link"/>
    <axis xyz="0 0 1"/>
    <limit lower="-3.054326190990076759616458844855" upper="3.054326190990076759616458844855" effort="13.5" start_stop="34" velocity="3.1105" />
    <property inertia="0.15" damping="0" stiffness="0" offset="0" motor_constant="7.092" ratio="101"/>
  </joint>
  <link name="wrist2_Link">
    <inertial>
      <origin rpy="0 0 0" xyz="-0.000038 -0.011278 -0.001539"/>
      <mass value="1.628022"/>
      <inertia ixx="0.001951" ixy="0.000003" ixz="-0.000001" iyy="0.001154" iyz="0.000042" izz="0.001931"/>
    </inertial>
    <visual>
      <origin rpy="0 0 0" xyz="0 0 0"/>
      <geometry>
        <mesh filename="package://aubo_description/meshes/aubo_i5L/visual/link5.DAE"/>
      </geometry>
      <material name="orange">
        <color rgba="1 0.65098 0 1"/>
      </material>
    </visual>
    <collision>
      <origin rpy="0 0 0" xyz="0 0 0"/>
      <geometry>
        <mesh filename="package://aubo_description/meshes/aubo_i5L/collision/link5.STL"/>
      </geometry>
    </collision>
  </link>
  <joint name="wrist2_joint" type="revolute">
    <origin rpy="-1.5707963267948966192313216916398 0 0" xyz="0 0.1025 0"/>
    <parent link="wrist1_Link"/>
    <child link="wrist2_Link"/>
    <axis xyz="0 0 1"/>
    <limit lower="-3.054326190990076759616458844855" upper="3.054326190990076759616458844855" effort="13.5" start_stop="34" velocity="3.1105" />
    <property inertia="0.15" damping="0" stiffness="0" offset="0" motor_constant="7.092" ratio="101"/>
  </joint>
  <link name="wrist3_Link">
    <inertial>
      <origin rpy="0 0 0" xyz="0.000022 0.0006 -0.017081"/>
      <mass value="0.1978"/>
      <inertia ixx="0.000118" ixy="0.0" ixz="0.0" iyy="0.000112" iyz="0.000001" izz="0.000184"/>
    </inertial>
    <visual>
      <origin rpy="0 0 0" xyz="0 0 0"/>
      <geometry>
        <mesh filename="package://aubo_description/meshes/aubo_i5L/visual/link6.DAE"/>
      </geometry>
      <material name="black">
        <color rgba="0.25098 0.25098 0.25098"/>
      </material>
    </visual>
    <collision>
      <origin rpy="0 0 0" xyz="0 0 0"/>
      <geometry>
        <mesh filename="package://aubo_description/meshes/aubo_i5L/collision/link6.STL"/>
      </geometry>
    </collision>
  </link>
  <joint name="wrist3_joint" type="revolute">
    <origin rpy="1.5707963267948966192313216916398 0 0" xyz="0 -0.094 0"/>
    <parent link="wrist2_Link"/>
    <child link="wrist3_Link"/>
    <axis xyz="0 0 1"/>
    <limit lower="-3.054326190990076759616458844855" upper="3.054326190990076759616458844855" effort="13.5" start_stop="34" velocity="3.1105" />
    <property inertia="0.15" damping="0" stiffness="0" offset="0" motor_constant="7.092" ratio="101"/>
  </joint>

  <link name="world" />

  <joint name="world_joint" type="fixed">
    <parent link="world" />
    <child link = "base_link" />
    <origin xyz="0.0 0.0 0.0" rpy="0.0 0.0 0.0" />
  </joint>
</robot>
