<?xml version="1.0"?>
<robot  name="aubo_S5">
  <dh_type type="modified"/>
  <safety_para singularity_consistent="0.02 0.01 10 0.2 0.045 10"/>	
  <link name="base_link">
    <inertial>
      <origin xyz="-1.4795E-13 0.0015384 0.020951" rpy="0 0 0" />
      <mass value="0.83419" />
      <inertia ixx="0.0014414" ixy="7.8809E-15" ixz="8.5328E-16" iyy="0.0013542" iyz="-1.4364E-05" izz="0.0024659" />
    </inertial>
    <visual>
      <origin xyz="0 0 0" rpy="0 0 0" />
      <geometry>
        <mesh filename="package://aubo_description/meshes/aubo_S5/visual/link0.DAE" />
      </geometry>
      <material name="">
        <color rgba="1 1 1 1" />
      </material>
    </visual>
    <collision>
      <origin xyz="0 0 0" rpy="0 0 0" />
      <geometry>
        <mesh filename="package://aubo_description/meshes/aubo_S5/collision/link0.STL" />
      </geometry>
    </collision>
  </link>

  <link name="shoulder_Link">
    <inertial>
      <origin xyz="0.00002503 0.00451895 -0.06744953" rpy="0 0 0" />
      <mass value="3.40870484" />
      <inertia ixx="0.02422618" ixy="0.0000013" ixz="0.00000248" iyy="0.02382946" iyz="-0.00009539" izz="0.00551813" />
    </inertial>
    <visual>
      <origin xyz="0 0 0" rpy="0 0 0" />
      <geometry>
        <mesh filename="package://aubo_description/meshes/aubo_S5/visual/link1.DAE" />
      </geometry>
      <material name="">
        <color rgba="1 1 1 1" />
      </material>
    </visual>
    <collision>
      <origin xyz="0 0 0" rpy="0 0 0" />
      <geometry>
        <mesh filename="package://aubo_description/meshes/aubo_S5/collision/link1.STL" />
      </geometry>
    </collision>
  </link>

  <joint name="shoulder_joint" type="revolute">
    <origin xyz="0 0 0.17090" rpy="0 0 3.1415926535897932384626433832795" />
    <parent link="base_link" />
    <child link="shoulder_Link" />
    <axis xyz="0 0 1" />
    <limit lower="-3.054326190990076759616458844855" upper="3.054326190990076759616458844855" effort="133" start_stop="207" velocity="2.5964" />
  </joint>

  <link name="upperArm_Link">
    <inertial>
      <origin xyz="0.18188358 0.00006498 -0.0114494" rpy="0 0 0" />
      <mass value="6.55471315" />
      <inertia ixx="0.01180878" ixy="-0.00017532" ixz="0.00758408" iyy="0.46224881" iyz="-0.00000295" izz="0.45975415 " />  	 	
    </inertial>
    <visual>
      <origin xyz="0 0 0" rpy="0 0 0" />
      <geometry>
        <mesh filename="package://aubo_description/meshes/aubo_S5/visual/link2.DAE" />
      </geometry>
      <material name="">
        <color rgba="1 1 1 1" />
      </material>
    </visual>
    <collision>
      <origin xyz="0 0 0" rpy="0 0 0" />
      <geometry>
        <mesh filename="package://aubo_description/meshes/aubo_S5/collision/link2.STL" />
      </geometry>
    </collision>
  </link>

  <joint name="upperArm_joint" type="revolute">
    <origin xyz="0 0.13211 0" rpy="-1.5707963267948966192313216916398 -1.5707963267948966192313216916398 0" />
    <parent link="shoulder_Link" />
    <child link="upperArm_Link" />
    <axis xyz="0 0 1" />
    <limit lower="-3.054326190990076759616458844855" upper="3.054326190990076759616458844855" effort="133" start_stop="207" velocity="2.5964" />
  </joint>

  <link name="foreArm_Link">
    <inertial>
      <origin xyz="0.23196077 0.00000675 0.09033381" rpy="0 0 0" />
      <mass  value="2.03993877" />
      <inertia ixx="0.01912263" ixy="-0.00000161" ixz="-0.04239393" iyy="0.16446448" iyz="-0.00000130" izz="0.14763471" />	 	 	 	 	 	 	 	 
    </inertial>
    <visual>
      <origin xyz="0 0 0" rpy="0 0 0" />
      <geometry>
        <mesh filename="package://aubo_description/meshes/aubo_S5/visual/link3.DAE" />
      </geometry>
      <material name="">
        <color rgba="1 1 1 1" />
      </material>
    </visual>
    <collision>
      <origin xyz="0 0 0" rpy="0 0 0" />
      <geometry>
        <mesh filename="package://aubo_description/meshes/aubo_S5/collision/link3.STL" />
      </geometry>
    </collision>
  </link>

  <joint name="foreArm_joint" type="revolute">
    <origin xyz="0.425 0 0" rpy="-3.1415926535897932384626433832795 0 0" />
    <parent link="upperArm_Link" />
    <child link="foreArm_Link" />
    <axis xyz="0 0 1" />
    <limit lower="-3.054326190990076759616458844855" upper="3.054326190990076759616458844855" effort="133" start_stop="207" velocity="2.5964" />
  </joint>

  <link name="wrist1_Link">
    <inertial>
      <origin xyz="-0.00038857 0.04279259 -0.00283649" rpy="0 0 0" />
      <mass value="1.06103669" />
      <inertia ixx="0.00339567" ixy="0.00001220" ixz="-0.00000422" iyy="0.00078060" iyz="0.00000169" izz="0.00334355" /> 	 
    </inertial>
    <visual>
      <origin xyz="0 0 0" rpy="0 0 0" />
      <geometry>
        <mesh filename="package://aubo_description/meshes/aubo_S5/visual/link4.DAE" />
      </geometry>
      <material name="">
        <color rgba="1 1 1 1" />
      </material>
    </visual>
    <collision>
      <origin xyz="0 0 0" rpy="0 0 0" />
      <geometry>
        <mesh filename="package://aubo_description/meshes/aubo_S5/collision/link4.STL" />
      </geometry>
    </collision>
  </link>

  <joint name="wrist1_joint" type="revolute">
    <origin xyz="0.3423 0 0" rpy="3.1415926535897932384626433832795 0 1.5707963267948966192313216916398" />
    <parent link="foreArm_Link" />
    <child link="wrist1_Link" />
    <axis xyz="0 0 1" />
    <limit lower="-3.054326190990076759616458844855" upper="3.054326190990076759616458844855" effort="13.5" start_stop="34" velocity="3.1105" />
  </joint>

  <link name="wrist2_Link">
    <inertial>
      <origin xyz="0.00010130 -0.04279419 -0.00283693" rpy="0 0 0" />
      <mass value="1.06103669" />
      <inertia ixx="0.00339571" ixy="-0.00000536" ixz="0.00000421" iyy="0.00078056" iyz="-0.00000175" izz="0.00334355" />	 	 	 	 	 	- 	 	 	 
    </inertial>
    <visual>
      <origin xyz="0 0 0" rpy="0 0 0" />
      <geometry>
        <mesh filename="package://aubo_description/meshes/aubo_S5/visual/link5.DAE" />
      </geometry>
      <material name="">
        <color rgba="1 1 1 1" />
      </material>
    </visual>
    <collision>
      <origin xyz="0 0 0" rpy="0 0 0" />
      <geometry>
        <mesh filename="package://aubo_description/meshes/aubo_S5/collision/link5.STL" />
      </geometry>
    </collision>
  </link>

  <joint name="wrist2_joint" type="revolute">
    <origin xyz="0 0.1305 0" rpy="-1.5707963267948966192313216916398 0 0" />
    <parent link="wrist1_Link" />
    <child link="wrist2_Link" />
    <axis xyz="0 0 1" />
    <limit lower="-3.054326190990076759616458844855" upper="3.054326190990076759616458844855" effort="13.5" start_stop="34" velocity="3.1105" />
  </joint>

  <link name="wrist3_Link">
    <inertial>
      <origin xyz="0.00090543 -0.00048829 -0.01870080" rpy="0 0 0" />
      <mass value="0.22222939" />
      <inertia ixx="0.00021030" ixy="0.00000398" ixz="0.00000545" iyy="0.00020993" iyz="-0.00000299" izz="0.00018334" />
    </inertial>
    <visual>
      <origin xyz="0 0 0" rpy="0 0 0" />
      <geometry>
        <mesh filename="package://aubo_description/meshes/aubo_S5/visual/link6.DAE" />
      </geometry>
      <material name="">
        <color rgba="1 1 1 1" />
      </material>
    </visual>
    <collision>
      <origin xyz="0 0 0" rpy="0 0 0" />
      <geometry>
        <mesh filename="package://aubo_description/meshes/aubo_S5/collision/link6.STL" />
      </geometry>
    </collision>
  </link>

  <joint name="wrist3_joint" type="revolute">
    <origin xyz="0 -0.1242 0" rpy="1.5707963267948966192313216916398 0 1.7907E-15" />
    <parent link="wrist2_Link" />
    <child link="wrist3_Link" />
    <axis xyz="0 0 1" />
    <limit lower="-3.054326190990076759616458844855" upper="3.054326190990076759616458844855" effort="13.5" start_stop="34" velocity="3.1105" />
  </joint>

  <link name="world" />

  <joint name="world_joint" type="fixed">
    <parent link="world" />
    <child link = "base_link" />
    <origin xyz="0.0 0.0 0.0" rpy="0.0 0.0 0.0" />
  </joint>
</robot>
