<?xml version="1.0"?>
<robot name="aubo_i5H_schaeffler">
  <dh_type type="modified"/>
  <safety_para singularity_consistent="0.02 0.01 10 0.2 0.045 10"/>
  <friction_coeff value="0.65"/>
  <link name="base_link">
    <inertial>
      <origin xyz="0.00012852 0.00124924 0.01667817" rpy="0 0 0" />
      <mass value="1.53901989" />
      <inertia ixx="0.00327826" ixy="-0.00000076" ixz="-0.0000014" iyy="0.0030174" iyz="-0.00008" izz="0.00584373" />
    </inertial>
    <visual>
      <origin xyz="0 0 0" rpy="0 0 0" />
      <geometry>
        <mesh filename="package://aubo_description/meshes/aubo_i5H_schaeffler/visual/link0.DAE" />
      </geometry>
      <material name="">
        <color rgba="1 1 1 1" />
      </material>
    </visual>
    <collision>
      <origin xyz="0 0 0" rpy="0 0 0" />
      <geometry>
        <mesh filename="package://aubo_description/meshes/aubo_i5H_schaeffler/collision/link0.STL" />
      </geometry>
    </collision>
  </link>

  <link name="shoulder_Link">
    <inertial>
      <origin xyz="-0.00003702 0.00167327 -0.01993005" rpy="0 0 0" />
      <mass value="5.0248149" />
      <inertia ixx="0.01212416" ixy="-0.00001147" ixz="0.00000104" iyy="0.01202782" iyz="-0.00013867" izz="0.00833814" />
    </inertial>
    <visual>
      <origin xyz="0 0 0" rpy="0 0 0" />
      <geometry>
        <mesh filename="package://aubo_description/meshes/aubo_i5H_schaeffler/visual/link1.DAE" />
      </geometry>
      <material name="">
        <color rgba="1 1 1 1" />
      </material>
    </visual>
    <collision>
      <origin xyz="0 0 0" rpy="0 0 0" />
      <geometry>
        <mesh filename="package://aubo_description/meshes/aubo_i5H_schaeffler/collision/link1.STL" />
      </geometry>
    </collision>
  </link>

  <joint name="shoulder_joint" type="revolute">
    <origin xyz="0 0 0.1225" rpy="0 0 3.1415926535897932384626433832795" />
    <parent link="base_link" />
    <child link="shoulder_Link" />
    <axis xyz="0 0 1" />
    <limit lower="-6.283185307179586476925286766559" upper="6.283185307179586476925286766559" effort="140" start_stop="204" velocity="3.1415926535897932384626433832795" />
    <property inertia="1.48972" damping="0" stiffness="0" offset="0" motor_constant="6.70842" ratio="101"/>
  </joint>

  <link name="upperArm_Link">
    <inertial>
      <origin xyz="0.20392823 0 -0.01141953" rpy="0 0 0" />
      <mass value="11.19552235" />
      <inertia ixx="0.02671361" ixy="0.00005637" ixz="-0.00004251" iyy="0.44882402" iyz="0.00000214" izz="0.44085807" />
    </inertial>
    <visual>
      <origin xyz="0 0 0" rpy="0 0 0" />
      <geometry>
        <mesh filename="package://aubo_description/meshes/aubo_i5H_schaeffler/visual/link2.DAE" />
      </geometry>
      <material name="">
        <color rgba="1 1 1 1" />
      </material>
    </visual>
    <collision>
      <origin xyz="0 0 0" rpy="0 0 0" />
      <geometry>
        <mesh filename="package://aubo_description/meshes/aubo_i5H_schaeffler/collision/link2.STL" />
      </geometry>
    </collision>
  </link>

  <joint name="upperArm_joint" type="revolute">
    <origin xyz="0 0.1345 0" rpy="-1.5707963267948966192313216916398 -1.5707963267948966192313216916398 0" />
    <parent link="shoulder_Link" />
    <child link="upperArm_Link" />
    <axis xyz="0 0 1" />
    <limit lower="-3.054326190990076759616458844855" upper="3.054326190990076759616458844855" effort="140" start_stop="204" velocity="3.1415926535897932384626433832795" />
    <property inertia="1.48972" damping="0" stiffness="0" offset="0" motor_constant="6.70842" ratio="101"/>
  </joint>

  <link name="foreArm_Link">
    <inertial>
      <origin xyz="0.23797774 0.00002623 0.10226946" rpy="0 0 0" />
      <mass value="3.416738" />
      <inertia ixx="0.00544722" ixy="-0.0000072" ixz="0.00190546" iyy="0.03424731" iyz="-0.00000411" izz="0.03264134" />			
    </inertial>
    <visual>
      <origin xyz="0 0 0" rpy="0 0 0" />
      <geometry>
        <mesh filename="package://aubo_description/meshes/aubo_i5H_schaeffler/visual/link3.DAE" />
      </geometry>
      <material name="">
        <color rgba="1 1 1 1" />
      </material>
    </visual>
    <collision>
      <origin xyz="0 0 0" rpy="0 0 0" />
      <geometry>
        <mesh filename="package://aubo_description/meshes/aubo_i5H_schaeffler/collision/link3.STL" />
      </geometry>
    </collision>
  </link>

  <joint name="foreArm_joint" type="revolute">
    <origin xyz="0.408 0 0" rpy="-3.1415926535897932384626433832795 0 0" />
    <parent link="upperArm_Link" />
    <child link="foreArm_Link" />
    <axis xyz="0 0 1" />
    <limit lower="-3.054326190990076759616458844855" upper="3.054326190990076759616458844855" effort="140" start_stop="204" velocity="3.1415926535897932384626433832795" />
    <property inertia="1.48972" damping="0" stiffness="0" offset="0" motor_constant="6.70842" ratio="101"/>
  </joint>

  <link name="wrist1_Link">
    <inertial>
      <origin xyz="-0.00003849 0.0208318 -0.00134581" rpy="0 0 0" />
      <mass value="2.33195365" />
      <inertia ixx="0.00367182" ixy="-0.00000334" ixz="0.00000221" iyy="0.00223668" iyz="-0.0000767" izz="0.00364712" />
    </inertial>
    <visual>
      <origin xyz="0 0 0" rpy="0 0 0" />
      <geometry>
        <mesh filename="package://aubo_description/meshes/aubo_i5H_schaeffler/visual/link4.DAE" />
      </geometry>
      <material name="">
        <color rgba="1 1 1 1" />
      </material>
    </visual>
    <collision>
      <origin xyz="0 0 0" rpy="0 0 0" />
      <geometry>
        <mesh filename="package://aubo_description/meshes/aubo_i5H_schaeffler/collision/link4.STL" />
      </geometry>
    </collision>
  </link>

  <joint name="wrist1_joint" type="revolute">
    <origin xyz="0.2945 0 0" rpy="3.1415926535897932384626433832795 0 1.5707963267948966192313216916398" />
    <parent link="foreArm_Link" />
    <child link="wrist1_Link" />
    <axis xyz="0 0 1" />
    <limit lower="-3.054326190990076759616458844855" upper="3.054326190990076759616458844855" effort="51" start_stop="70" velocity="3.1415926535897932384626433832795" />
    <property inertia="0.50925" damping="0" stiffness="0" offset="0" motor_constant="6.75488" ratio="101"/>
  </joint>

  <link name="wrist2_Link">
    <inertial>
      <origin xyz="0.00003849 -0.0208318 -0.00134581" rpy="0 0 0" />
      <mass value="2.33195365" />
      <inertia ixx="0.00367182" ixy="-0.00000334" ixz="-0.00000221" iyy="0.0022409" iyz="0.00001133" izz="0.0046591" />
    </inertial>
    <visual>
      <origin xyz="0 0 0" rpy="0 0 0" />
      <geometry>
        <mesh filename="package://aubo_description/meshes/aubo_i5H_schaeffler/visual/link5.DAE" />
      </geometry>
      <material name="">
        <color rgba="1 1 1 1" />
      </material>
    </visual>
    <collision>
      <origin xyz="0 0 0" rpy="0 0 0" />
      <geometry>
        <mesh filename="package://aubo_description/meshes/aubo_i5H_schaeffler/collision/link5.STL" />
      </geometry>
    </collision>
  </link>

  <joint name="wrist2_joint" type="revolute">
    <origin xyz="0 0.1175 0" rpy="-1.5707963267948966192313216916398 0 0" />
    <parent link="wrist1_Link" />
    <child link="wrist2_Link" />
    <axis xyz="0 0 1" />
    <limit lower="-3.054326190990076759616458844855" upper="3.054326190990076759616458844855" effort="51" start_stop="70" velocity="3.1415926535897932384626433832795" />
    <property inertia="0.50925" damping="0" stiffness="0" offset="0" motor_constant="6.75488" ratio="101"/>
  </joint>

  <link name="wrist3_Link">
    <inertial>
      <origin xyz="0.00013306 0.00049329 -0.01709171" rpy="0 0 0" />
      <mass value="0.21595085" />
      <inertia ixx="0.0001462" ixy="-0.00000019" ixz="0.00000002" iyy="0.00014279" iyz="0.00000114" izz="0.00024327" />	
    </inertial>
    <visual>
      <origin xyz="0 0 0" rpy="0 0 0" />
      <geometry>
        <mesh filename="package://aubo_description/meshes/aubo_i5H_schaeffler/visual/link6.DAE" />
      </geometry>
      <material name="">
        <color rgba="1 1 1 1" />
      </material>
    </visual>
    <collision>
      <origin xyz="0 0 0" rpy="0 0 0" />
      <geometry>
        <mesh filename="package://aubo_description/meshes/aubo_i5H_schaeffler/collision/link6.STL" />
      </geometry>
    </collision>
  </link>

  <joint name="wrist3_joint" type="revolute">
    <origin xyz="0 -0.1035 0" rpy="1.5707963267948966192313216916398 0 0" />
    <parent link="wrist2_Link" />
    <child link="wrist3_Link" />
    <axis xyz="0 0 1" />
    <limit lower="-6.283185307179586476925286766559" upper="6.283185307179586476925286766559" effort="51" start_stop="70" velocity="3.1415926535897932384626433832795" />
    <property inertia="0.21928069650925" damping="0" stiffness="0" offset="0" motor_constant="6.75488" ratio="101"/>
  </joint>

  <link name="world" />

  <joint name="world_joint" type="fixed">
    <parent link="world" />
    <child link = "base_link" />
    <origin xyz="0.0 0.0 0.0" rpy="0.0 0.0 0.0" />
  </joint>
</robot>
