<?xml version="1.0"?>
<robot  name="cf_SF6C1400X_6KG_QN">
  <dh_type type="modified"/>
  <safety_para singularity_consistent="0.02 0.01 10 0.2 0.045 10"/>
  <friction_coeff value="0.5"/>	
  <link name="base_link">
    <inertial>
      <origin xyz="0.07089 0.00086 -0.137728" rpy="0 0 0" />
      <mass value="50.83419" />
      <inertia ixx="1.396797711" ixy="0.026187817" ixz="0.477372205" iyy="1.562519092" iyz="0.070691273" izz="1.190714506" />
    </inertial>
    <visual>
      <origin xyz="0 0 0" rpy="0 0 0" />
      <geometry>
        <mesh filename="package://aubo_description/meshes/cf_SF6C1400X_6KG_QN/visual/link0.3ds" />
      </geometry>
      <material name="">
        <color rgba="1 1 1 1" />
      </material>
    </visual>
    <collision>
      <origin xyz="0 0 0" rpy="0 0 0" />
      <geometry>
        <mesh filename="package://aubo_description/meshes/cf_SF6C1400X_6KG_QN/collision/link0.STL" />
      </geometry>
    </collision>
  </link>

  <link name="shoulder_Link">
    <inertial>
      <origin xyz="0.07089 0.00086 -0.137728" rpy="0 0 0" />
      <mass value="67.108" />
      <inertia ixx="1.396797711" ixy="0.026187817" ixz="0.477372205" iyy="1.562519092" iyz="0.070691273" izz="1.190714506" />
    </inertial>
    <visual>
      <origin xyz="0 0 0" rpy="0 0 0" />
      <geometry>
        <mesh filename="package://aubo_description/meshes/cf_SF6C1400X_6KG_QN/visual/link1.3ds" />
      </geometry>
      <material name="">
        <color rgba="1 1 1 1" />
      </material>
    </visual>
    <collision>
      <origin xyz="0 0 0" rpy="0 0 0" />
      <geometry>
        <mesh filename="package://aubo_description/meshes/cf_SF6C1400X_6KG_QN/collision/link1.STL" />
      </geometry>
    </collision>
  </link>

  <joint name="shoulder_joint" type="revolute">
    <origin xyz="0 0 0.4304" rpy="0 0 -1.5707963267948966192313216916398" />
    <parent link="base_link" />
    <child link="shoulder_Link" />
    <axis xyz="0 0 1" />
    <limit lower="-6.283185307179586476925286766559" upper="6.283185307179586476925286766559" effort="2979" start_stop="0" velocity="6.2832" />
  </joint>

  <link name="upperArm_Link">
    <inertial>
      <origin xyz="0.377523 0.017610 0.095389" rpy="0 0 0" />
      <mass value="14.482" />
      <inertia ixx="0.052469781" ixy="-0.018188112" ixz="-0.072551382" iyy="0.752890295" iyz="0.006979824" izz="0.760648350" />
    </inertial>
    <visual>
      <origin xyz="0 0 0" rpy="0 0 0" />
      <geometry>
        <mesh filename="package://aubo_description/meshes/cf_SF6C1400X_6KG_QN/visual/link2.3ds" />
      </geometry>
      <material name="">
        <color rgba="1 1 1 1" />
      </material>
    </visual>
    <collision>
      <origin xyz="0 0 0" rpy="0 0 0" />
      <geometry>
        <mesh filename="package://aubo_description/meshes/cf_SF6C1400X_6KG_QN/collision/link2.STL" />
      </geometry>
    </collision>
  </link>

  <joint name="upperArm_joint" type="revolute">
    <origin xyz="0.16 0 0" rpy="1.5707963267948966192313216916398 -1.5707963267948966192313216916398 0" />
    <parent link="shoulder_Link" />
    <child link="upperArm_Link" />
    <axis xyz="0 0 1" />
    <limit lower="-2.4" upper="2.4" effort="2979" start_stop="0" velocity="3.1415926535897932384626433832795" />
  </joint>

  <link name="foreArm_Link">
    <inertial>
      <origin xyz="0.122903 -0.087866 0.014286" rpy="0 0 0" />
      <mass  value="19.624" />
      <inertia ixx="0.183780626" ixy="-0.075411021" ixz="0.041565688" iyy="0.255468215" iyz="-0.028110950" izz="0.261417540" />
    </inertial>
    <visual>
      <origin xyz="0 0 0" rpy="0 0 0" />
      <geometry>
        <mesh filename="package://aubo_description/meshes/cf_SF6C1400X_6KG_QN/visual/link3.3ds" />
      </geometry>
      <material name="">
        <color rgba="1 1 1 1" />
      </material>
    </visual>
    <collision>
      <origin xyz="0 0 0" rpy="0 0 0" />
      <geometry>
        <mesh filename="package://aubo_description/meshes/cf_SF6C1400X_6KG_QN/collision/link3.STL" />
      </geometry>
    </collision>
  </link>

  <joint name="foreArm_joint" type="revolute">
    <origin xyz="0.615 0 0" rpy="0 0 0" />
    <parent link="upperArm_Link" />
    <child link="foreArm_Link" />
    <axis xyz="0 0 1" />
    <limit lower="-2.4" upper="2.4" effort="927" start_stop="0" velocity="3.1415926535897932384626433832795" />
  </joint>

  <link name="wrist1_Link">
    <inertial>
      <origin xyz="0.0461 -0.029557 -0.252628" rpy="0 0 0" />
      <mass value="12.470" />
      <inertia ixx="0.29934248" ixy="0.001259955" ixz="-0.006192377" iyy="0.304310654" iyz="0.056077903" izz="0.075809248" />
    </inertial>
    <visual>
      <origin xyz="0 0 0" rpy="0 0 0" />
      <geometry>
        <mesh filename="package://aubo_description/meshes/cf_SF6C1400X_6KG_QN/visual/link4.3ds" />
      </geometry>
      <material name="">
        <color rgba="1 1 1 1" />
      </material>
    </visual>
    <collision>
      <origin xyz="0 0 0" rpy="0 0 0" />
      <geometry>
        <mesh filename="package://aubo_description/meshes/cf_SF6C1400X_6KG_QN/collision/link4.STL" />
      </geometry>
    </collision>
  </link>

  <joint name="wrist1_joint" type="revolute">
    <origin xyz="0.2 -0.6405 0" rpy="1.5707963267948966192313216916398 0 0" />
    <parent link="foreArm_Link" />
    <child link="wrist1_Link" />
    <axis xyz="0 0 1" />
    <limit lower="-6.283185307179586476925286766559" upper="6.283185307179586476925286766559" effort="303" start_stop="0" velocity="6.283185307179586476925286766559" />
  </joint>

  <link name="wrist2_Link">
    <inertial>
      <origin xyz="-0.000073 -0.046266 -0.062413" rpy="0 0 0" />
      <mass value="3.064" />
      <inertia ixx="0.008054391" ixy="-0.000002564" ixz="-0.00000354" iyy="0.006562182" iyz="0.002036081" izz="0.006520876" />
    </inertial>
    <visual>
      <origin xyz="0 0 0" rpy="0 0 0" />
      <geometry>
        <mesh filename="package://aubo_description/meshes/cf_SF6C1400X_6KG_QN/visual/link5.3ds" />
      </geometry>
      <material name="">
        <color rgba="1 1 1 1" />
      </material>
    </visual>
    <collision>
      <origin xyz="0 0 0" rpy="0 0 0" />
      <geometry>
        <mesh filename="package://aubo_description/meshes/cf_SF6C1400X_6KG_QN/collision/link5.STL" />
      </geometry>
    </collision>
  </link>

  <joint name="wrist2_joint" type="revolute">
    <origin xyz="0 0 0" rpy="-1.5707963267948966192313216916398 -1.5707963267948966192313216916398 0" />
    <parent link="wrist1_Link" />
    <child link="wrist2_Link" />
    <axis xyz="0 0 1" />
    <limit lower="-2.4" upper="2.4" effort="156" start_stop="0" velocity="6.283185307179586476925286766559" />
  </joint>

  <link name="wrist3_Link">
    <inertial>
      <origin xyz="-0.003522 -0.000072 -0.038873" rpy="0 0 0" />
      <mass value="1.414" />
      <inertia ixx="0.001894374" ixy="0.000004074" ixz="0.000288792" iyy="0.002120817" iyz="0.000001185" izz="0.001856818" />
    </inertial>
    <visual>
      <origin xyz="0 0 0" rpy="0 0 0" />
      <geometry>
        <mesh filename="package://aubo_description/meshes/cf_SF6C1400X_6KG_QN/visual/link6.3ds" />
      </geometry>
      <material name="">
        <color rgba="1 1 1 1" />
      </material>
    </visual>
    <collision>
      <origin xyz="0 0 0" rpy="0 0 0" />
      <geometry>
        <mesh filename="package://aubo_description/meshes/cf_SF6C1400X_6KG_QN/collision/link6.STL" />
      </geometry>
    </collision>
  </link>

  <joint name="wrist3_joint" type="revolute">
    <origin xyz="0 -0.0995 0" rpy="1.5707963267948966192313216916398 1.5707963267948966192313216916398 0" />
    <parent link="wrist2_Link" />
    <child link="wrist3_Link" />
    <axis xyz="0 0 1" />
    <limit lower="-6.283185307179586476925286766559" upper="6.283185307179586476925286766559" effort="67" start_stop="0" velocity="6.283185307179586476925286766559" />
  </joint>

  <link name="world" />

  <joint name="world_joint" type="fixed">
    <parent link="world" />
    <child link = "base_link" />
    <origin xyz="0.0 0.0 0.0" rpy="0.0 0.0 0.0" />
  </joint>
</robot>
